Workbook

Sheet 📊 Дашборд
A1: ДАШБОРД · АВТОМАТИЗАЦИЯ СЦ СОЛВО 2026
A4: Всего задач | B4: Выполнено | C4: В работе | D4: Ч/часов (оценка) | E4: % выполнено
A5: ='Судовые документы'!A4+'Таможенные документы'!A4+'Экспортные грузы'!A4+Терминал!A4+'ЖД грузы'!A4 -> 43 | B5: ='Судовые документы'!B4+'Таможенные документы'!B4+'Экспортные грузы'!B4+Терминал!B4+'ЖД грузы'!B4 -> 14 | C5: ='Судовые документы'!C4+'Таможенные документы'!C4+'Экспортные грузы'!C4+Терминал!C4+'ЖД грузы'!C4 -> 7 | D5: ='Судовые документы'!D4+'Таможенные документы'!D4+'Экспортные грузы'!D4+Терминал!D4+'ЖД грузы'!D4 -> 3231 | E5: =IF(('Судовые документы'!A4+'Таможенные документы'!A4+'Экспортные грузы'!A4+Терминал!A4+'ЖД грузы'!A4)=0,0,('Судовые документы'!B4+'Таможенные документы'!B4+'Экспортные грузы'!B4+Терминал!B4+'ЖД грузы'!B4)/('Судовые документы'!A4+'Таможенные документы'!A4+'Экспортные грузы'!A4+Терминал!A4+'ЖД грузы'!A4)) -> 0.3255814
D6: =IFERROR(D5='📋 Реестр'!I52,"0") -> TRUE
A7: Категория / Раздел | B7: Всего | C7: Выполнено | D7: В работе | E7: Ч/часов | F7: % готовности
A8: Обработка судовых документов | B8: ='Судовые документы'!A4 -> 7 | C8: ='Судовые документы'!B4 -> 2 | D8: ='Судовые документы'!C4 -> 3 | E8: ='Судовые документы'!D4 -> 513 | F8: =IF('Судовые документы'!A4=0,0,'Судовые документы'!B4/'Судовые документы'!A4) -> 0.28571429
A9: Оформление таможенных документов | B9: ='Таможенные документы'!A4 -> 5 | C9: ='Таможенные документы'!B4 -> 1 | D9: ='Таможенные документы'!C4 -> 0 | E9: ='Таможенные документы'!D4 -> 780 | F9: =IF('Таможенные документы'!A4=0,0,'Таможенные документы'!B4/'Таможенные документы'!A4) -> 0.2
A10: Оформление экспортных грузов | B10: ='Экспортные грузы'!A4 -> 5 | C10: ='Экспортные грузы'!B4 -> 2 | D10: ='Экспортные грузы'!C4 -> 1 | E10: ='Экспортные грузы'!D4 -> 532 | F10: =IF('Экспортные грузы'!A4=0,0,'Экспортные грузы'!B4/'Экспортные грузы'!A4) -> 0.4
A11: Терминальные операции | B11: =Терминал!A4 -> 16 | C11: =Терминал!B4 -> 8 | D11: =Терминал!C4 -> 2 | E11: =Терминал!D4 -> 1231 | F11: =IF(Терминал!A4=0,0,Терминал!B4/Терминал!A4) -> 0.5
A12: Документальное оформление ЖД грузов | B12: ='ЖД грузы'!A4 -> 10 | C12: ='ЖД грузы'!B4 -> 1 | D12: ='ЖД грузы'!C4 -> 1 | E12: ='ЖД грузы'!D4 -> 175 | F12: =IF('ЖД грузы'!A4=0,0,'ЖД грузы'!B4/'ЖД грузы'!A4) -> 0.1
A13: ИТОГО | B13: =SUM(B8:B12) -> 43 | C13: =SUM(C8:C12) -> 14 | D13: =SUM(D8:D12) -> 7 | E13: =SUM(E8:E12) -> 3231 | F13: =IF(B13=0,0,C13/B13) -> 0.3255814
A15: Разбивка по статусу СОЛВО | E15: Задачи по релизам
A16: Установлено | B16: =COUNTIF('Судовые документы'!G6:G12,"Установлено")+COUNTIF('Таможенные документы'!G6:G10,"Установлено")+COUNTIF('Экспортные грузы'!G6:G10,"Установлено")+COUNTIF(Терминал!G6:G21,"Установлено")+COUNTIF('ЖД грузы'!G6:G15,"Установлено") -> 12 | C16: =IF(('Судовые документы'!A4+'Таможенные документы'!A4+'Экспортные грузы'!A4+Терминал!A4+'ЖД грузы'!A4)=0,0,B16/('Судовые документы'!A4+'Таможенные документы'!A4+'Экспортные грузы'!A4+Терминал!A4+'ЖД грузы'!A4)) -> 0.27906977 | E16: Релиз | F16: Кол-во задач | G16: Ч/часов
A17: ОПЭ | B17: =COUNTIF('Судовые документы'!G6:G12,"ОПЭ")+COUNTIF('Таможенные документы'!G6:G10,"ОПЭ")+COUNTIF('Экспортные грузы'!G6:G10,"ОПЭ")+COUNTIF(Терминал!G6:G21,"ОПЭ")+COUNTIF('ЖД грузы'!G6:G15,"ОПЭ") -> 0 | C17: =IF(('Судовые документы'!A4+'Таможенные документы'!A4+'Экспортные грузы'!A4+Терминал!A4+'ЖД грузы'!A4)=0,0,B17/('Судовые документы'!A4+'Таможенные документы'!A4+'Экспортные грузы'!A4+Терминал!A4+'ЖД грузы'!A4)) -> 0 | E17: 7.4.4 | F17: =COUNTIF('Судовые документы'!H6:H12,"7.4.4")+COUNTIF('Таможенные документы'!H6:H10,"7.4.4")+COUNTIF('Экспортные грузы'!H6:H10,"7.4.4")+COUNTIF(Терминал!H6:H21,"7.4.4")+COUNTIF('ЖД грузы'!H6:H15,"7.4.4") -> 1 | G17: =SUMIF('Судовые документы'!H6:H12,"7.4.4",'Судовые документы'!I6:I12)+SUMIF('Таможенные документы'!H6:H10,"7.4.4",'Таможенные документы'!I6:I10)+SUMIF('Экспортные грузы'!H6:H10,"7.4.4",'Экспортные грузы'!I6:I10)+SUMIF(Терминал!H6:H21,"7.4.4",Терминал!I6:I21)+SUMIF('ЖД грузы'!H6:H15,"7.4.4",'ЖД грузы'!I6:I15) -> 780
A18: Тестирование | B18: =COUNTIF('Судовые документы'!G6:G12,"Тестирование")+COUNTIF('Таможенные документы'!G6:G10,"Тестирование")+COUNTIF('Экспортные грузы'!G6:G10,"Тестирование")+COUNTIF(Терминал!G6:G21,"Тестирование")+COUNTIF('ЖД грузы'!G6:G15,"Тестирование") -> 6 | C18: =IF(('Судовые документы'!A4+'Таможенные документы'!A4+'Экспортные грузы'!A4+Терминал!A4+'ЖД грузы'!A4)=0,0,B18/('Судовые документы'!A4+'Таможенные документы'!A4+'Экспортные грузы'!A4+Терминал!A4+'ЖД грузы'!A4)) -> 0.13953488 | E18: 7.4.5 | F18: =COUNTIF('Судовые документы'!H6:H12,"7.4.5")+COUNTIF('Таможенные документы'!H6:H10,"7.4.5")+COUNTIF('Экспортные грузы'!H6:H10,"7.4.5")+COUNTIF(Терминал!H6:H21,"7.4.5")+COUNTIF('ЖД грузы'!H6:H15,"7.4.5") -> 2 | G18: =SUMIF('Судовые документы'!H6:H12,"7.4.5",'Судовые документы'!I6:I12)+SUMIF('Таможенные документы'!H6:H10,"7.4.5",'Таможенные документы'!I6:I10)+SUMIF('Экспортные грузы'!H6:H10,"7.4.5",'Экспортные грузы'!I6:I10)+SUMIF(Терминал!H6:H21,"7.4.5",Терминал!I6:I21)+SUMIF('ЖД грузы'!H6:H15,"7.4.5",'ЖД грузы'!I6:I15) -> 110
A19: В работе | B19: =COUNTIF('Судовые документы'!G6:G12,"В работе")+COUNTIF('Таможенные документы'!G6:G10,"В работе")+COUNTIF('Экспортные грузы'!G6:G10,"В работе")+COUNTIF(Терминал!G6:G21,"В работе")+COUNTIF('ЖД грузы'!G6:G15,"В работе") -> 0 | C19: =IF(('Судовые документы'!A4+'Таможенные документы'!A4+'Экспортные грузы'!A4+Терминал!A4+'ЖД грузы'!A4)=0,0,B19/('Судовые документы'!A4+'Таможенные документы'!A4+'Экспортные грузы'!A4+Терминал!A4+'ЖД грузы'!A4)) -> 0 | E19: 7.4.7 | F19: =COUNTIF('Судовые документы'!H6:H12,"7.4.7")+COUNTIF('Таможенные документы'!H6:H10,"7.4.7")+COUNTIF('Экспортные грузы'!H6:H10,"7.4.7")+COUNTIF(Терминал!H6:H21,"7.4.7")+COUNTIF('ЖД грузы'!H6:H15,"7.4.7") -> 3 | G19: =SUMIF('Судовые документы'!H6:H12,"7.4.7",'Судовые документы'!I6:I12)+SUMIF('Таможенные документы'!H6:H10,"7.4.7",'Таможенные документы'!I6:I10)+SUMIF('Экспортные грузы'!H6:H10,"7.4.7",'Экспортные грузы'!I6:I10)+SUMIF(Терминал!H6:H21,"7.4.7",Терминал!I6:I21)+SUMIF('ЖД грузы'!H6:H15,"7.4.7",'ЖД грузы'!I6:I15) -> 220
A20: Разработка | B20: =COUNTIF('Судовые документы'!G6:G12,"Разработка")+COUNTIF('Таможенные документы'!G6:G10,"Разработка")+COUNTIF('Экспортные грузы'!G6:G10,"Разработка")+COUNTIF(Терминал!G6:G21,"Разработка")+COUNTIF('ЖД грузы'!G6:G15,"Разработка") -> 1 | C20: =IF(('Судовые документы'!A4+'Таможенные документы'!A4+'Экспортные грузы'!A4+Терминал!A4+'ЖД грузы'!A4)=0,0,B20/('Судовые документы'!A4+'Таможенные документы'!A4+'Экспортные грузы'!A4+Терминал!A4+'ЖД грузы'!A4)) -> 0.023255814 | E20: 7.4.8 | F20: =COUNTIF('Судовые документы'!H6:H12,"7.4.8")+COUNTIF('Таможенные документы'!H6:H10,"7.4.8")+COUNTIF('Экспортные грузы'!H6:H10,"7.4.8")+COUNTIF(Терминал!H6:H21,"7.4.8")+COUNTIF('ЖД грузы'!H6:H15,"7.4.8") -> 4 | G20: =SUMIF('Судовые документы'!H6:H12,"7.4.8",'Судовые документы'!I6:I12)+SUMIF('Таможенные документы'!H6:H10,"7.4.8",'Таможенные документы'!I6:I10)+SUMIF('Экспортные грузы'!H6:H10,"7.4.8",'Экспортные грузы'!I6:I10)+SUMIF(Терминал!H6:H21,"7.4.8",Терминал!I6:I21)+SUMIF('ЖД грузы'!H6:H15,"7.4.8",'ЖД грузы'!I6:I15) -> 214
A21: Аналитика | B21: =COUNTIF('Судовые документы'!G6:G12,"Аналитика")+COUNTIF('Таможенные документы'!G6:G10,"Аналитика")+COUNTIF('Экспортные грузы'!G6:G10,"Аналитика")+COUNTIF(Терминал!G6:G21,"Аналитика")+COUNTIF('ЖД грузы'!G6:G15,"Аналитика") -> 9 | C21: =IF(('Судовые документы'!A4+'Таможенные документы'!A4+'Экспортные грузы'!A4+Терминал!A4+'ЖД грузы'!A4)=0,0,B21/('Судовые документы'!A4+'Таможенные документы'!A4+'Экспортные грузы'!A4+Терминал!A4+'ЖД грузы'!A4)) -> 0.20930233 | E21: 7.4.9 | F21: =COUNTIF('Судовые документы'!H6:H12,"7.4.9")+COUNTIF('Таможенные документы'!H6:H10,"7.4.9")+COUNTIF('Экспортные грузы'!H6:H10,"7.4.9")+COUNTIF(Терминал!H6:H21,"7.4.9")+COUNTIF('ЖД грузы'!H6:H15,"7.4.9") -> 4 | G21: =SUMIF('Судовые документы'!H6:H12,"7.4.9",'Судовые документы'!I6:I12)+SUMIF('Таможенные документы'!H6:H10,"7.4.9",'Таможенные документы'!I6:I10)+SUMIF('Экспортные грузы'!H6:H10,"7.4.9",'Экспортные грузы'!I6:I10)+SUMIF(Терминал!H6:H21,"7.4.9",Терминал!I6:I21)+SUMIF('ЖД грузы'!H6:H15,"7.4.9",'ЖД грузы'!I6:I15) -> 441
A22: Оценка | B22: =COUNTIF('Судовые документы'!G6:G12,"Оценка")+COUNTIF('Таможенные документы'!G6:G10,"Оценка")+COUNTIF('Экспортные грузы'!G6:G10,"Оценка")+COUNTIF(Терминал!G6:G21,"Оценка")+COUNTIF('ЖД грузы'!G6:G15,"Оценка") -> 4 | C22: =IF(('Судовые документы'!A4+'Таможенные документы'!A4+'Экспортные грузы'!A4+Терминал!A4+'ЖД грузы'!A4)=0,0,B22/('Судовые документы'!A4+'Таможенные документы'!A4+'Экспортные грузы'!A4+Терминал!A4+'ЖД грузы'!A4)) -> 0.093023256 | E22: 7.4.10 | F22: =COUNTIF('Судовые документы'!H6:H12,"7.4.10")+COUNTIF('Таможенные документы'!H6:H10,"7.4.10")+COUNTIF('Экспортные грузы'!H6:H10,"7.4.10")+COUNTIF(Терминал!H6:H21,"7.4.10")+COUNTIF('ЖД грузы'!H6:H15,"7.4.10") -> 8 | G22: =SUMIF('Судовые документы'!H6:H12,"7.4.10",'Судовые документы'!I6:I12)+SUMIF('Таможенные документы'!H6:H10,"7.4.10",'Таможенные документы'!I6:I10)+SUMIF('Экспортные грузы'!H6:H10,"7.4.10",'Экспортные грузы'!I6:I10)+SUMIF(Терминал!H6:H21,"7.4.10",Терминал!I6:I21)+SUMIF('ЖД грузы'!H6:H15,"7.4.10",'ЖД грузы'!I6:I15) -> 892
A23: Ожидает рассмотрения | B23: =COUNTIF('Судовые документы'!G6:G12,"Ожидает рассмотрения")+COUNTIF('Таможенные документы'!G6:G10,"Ожидает рассмотрения")+COUNTIF('Экспортные грузы'!G6:G10,"Ожидает рассмотрения")+COUNTIF(Терминал!G6:G21,"Ожидает рассмотрения")+COUNTIF('ЖД грузы'!G6:G15,"Ожидает рассмотрения") -> 6 | C23: =IF(('Судовые документы'!A4+'Таможенные документы'!A4+'Экспортные грузы'!A4+Терминал!A4+'ЖД грузы'!A4)=0,0,B23/('Судовые документы'!A4+'Таможенные документы'!A4+'Экспортные грузы'!A4+Терминал!A4+'ЖД грузы'!A4)) -> 0.13953488 | E23: 7.4.11 | F23: =COUNTIF('Судовые документы'!H6:H12,"7.4.11")+COUNTIF('Таможенные документы'!H6:H10,"7.4.11")+COUNTIF('Экспортные грузы'!H6:H10,"7.4.11")+COUNTIF(Терминал!H6:H21,"7.4.11")+COUNTIF('ЖД грузы'!H6:H15,"7.4.11") -> 16 | G23: =SUMIF('Судовые документы'!H6:H12,"7.4.11",'Судовые документы'!I6:I12)+SUMIF('Таможенные документы'!H6:H10,"7.4.11",'Таможенные документы'!I6:I10)+SUMIF('Экспортные грузы'!H6:H10,"7.4.11",'Экспортные грузы'!I6:I10)+SUMIF(Терминал!H6:H21,"7.4.11",Терминал!I6:I21)+SUMIF('ЖД грузы'!H6:H15,"7.4.11",'ЖД грузы'!I6:I15) -> 574
A24: Приостановлена | B24: =COUNTIF('Судовые документы'!G6:G12,"Приостановлена")+COUNTIF('Таможенные документы'!G6:G10,"Приостановлена")+COUNTIF('Экспортные грузы'!G6:G10,"Приостановлена")+COUNTIF(Терминал!G6:G21,"Приостановлена")+COUNTIF('ЖД грузы'!G6:G15,"Приостановлена") -> 1 | C24: =IF(('Судовые документы'!A4+'Таможенные документы'!A4+'Экспортные грузы'!A4+Терминал!A4+'ЖД грузы'!A4)=0,0,B24/('Судовые документы'!A4+'Таможенные документы'!A4+'Экспортные грузы'!A4+Терминал!A4+'ЖД грузы'!A4)) -> 0.023255814 | E24: 7.4.12 | F24: =COUNTIF('Судовые документы'!H6:H12,"7.4.12")+COUNTIF('Таможенные документы'!H6:H10,"7.4.12")+COUNTIF('Экспортные грузы'!H6:H10,"7.4.12")+COUNTIF(Терминал!H6:H21,"7.4.12")+COUNTIF('ЖД грузы'!H6:H15,"7.4.12") -> 0 | G24: =SUMIF('Судовые документы'!H6:H12,"7.4.12",'Судовые документы'!I6:I12)+SUMIF('Таможенные документы'!H6:H10,"7.4.12",'Таможенные документы'!I6:I10)+SUMIF('Экспортные грузы'!H6:H10,"7.4.12",'Экспортные грузы'!I6:I10)+SUMIF(Терминал!H6:H21,"7.4.12",Терминал!I6:I21)+SUMIF('ЖД грузы'!H6:H15,"7.4.12",'ЖД грузы'!I6:I15) -> 0
A25: На приемке | B25: =COUNTIF('Судовые документы'!G6:G12,"На приемке")+COUNTIF('Таможенные документы'!G6:G10,"На приемке")+COUNTIF('Экспортные грузы'!G6:G10,"На приемке")+COUNTIF(Терминал!G6:G21,"На приемке")+COUNTIF('ЖД грузы'!G6:G15,"На приемке") -> 0 | C25: =IF(('Судовые документы'!A4+'Таможенные документы'!A4+'Экспортные грузы'!A4+Терминал!A4+'ЖД грузы'!A4)=0,0,B25/('Судовые документы'!A4+'Таможенные документы'!A4+'Экспортные грузы'!A4+Терминал!A4+'ЖД грузы'!A4)) -> 0 | E25: Не СОЛВО | F25: =COUNTIF('Судовые документы'!H6:H12,"Не СОЛВО")+COUNTIF('Таможенные документы'!H6:H10,"Не СОЛВО")+COUNTIF('Экспортные грузы'!H6:H10,"Не СОЛВО")+COUNTIF(Терминал!H6:H21,"Не СОЛВО")+COUNTIF('ЖД грузы'!H6:H15,"Не СОЛВО") -> 2 | G25: =SUMIF('Судовые документы'!H7:H13,"Не СОЛВО",'Судовые документы'!I7:I13)+SUMIF('Таможенные документы'!H7:H11,"Не СОЛВО",'Таможенные документы'!I7:I11)+SUMIF('Экспортные грузы'!H7:H11,"Не СОЛВО",'Экспортные грузы'!I7:I11)+SUMIF(Терминал!H7:H22,"Не СОЛВО",Терминал!I7:I22)+SUMIF('ЖД грузы'!H7:H16,"Не СОЛВО",'ЖД грузы'!I7:I16) -> 0
A26: Не СОЛВО | B26: =COUNTIF('Судовые документы'!G6:G12,"Не СОЛВО")+COUNTIF('Таможенные документы'!G6:G10,"Не СОЛВО")+COUNTIF('Экспортные грузы'!G6:G10,"Не СОЛВО")+COUNTIF(Терминал!G6:G21,"Не СОЛВО")+COUNTIF('ЖД грузы'!G6:G15,"Не СОЛВО") -> 2 | C26: =IF(('Судовые документы'!A4+'Таможенные документы'!A4+'Экспортные грузы'!A4+Терминал!A4+'ЖД грузы'!A4)=0,0,B26/('Судовые документы'!A4+'Таможенные документы'!A4+'Экспортные грузы'!A4+Терминал!A4+'ЖД грузы'!A4)) -> 0.046511628 | E26: Н/Д | F26: =COUNTIF('Судовые документы'!H6:H12,"Н/Д")+COUNTIF('Таможенные документы'!H6:H10,"Н/Д")+COUNTIF('Экспортные грузы'!H6:H10,"Н/Д")+COUNTIF(Терминал!H6:H21,"Н/Д")+COUNTIF('ЖД грузы'!H6:H15,"Н/Д") -> 3 | G26: =SUMIF('Судовые документы'!H8:H14,"7.4.12",'Судовые документы'!I8:I14)+SUMIF('Таможенные документы'!H8:H12,"7.4.12",'Таможенные документы'!I8:I12)+SUMIF('Экспортные грузы'!H8:H12,"7.4.12",'Экспортные грузы'!I8:I12)+SUMIF(Терминал!H8:H23,"7.4.12",Терминал!I8:I23)+SUMIF('ЖД грузы'!H8:H17,"7.4.12",'ЖД грузы'!I8:I17) -> 0
A27: Н/Д | B27: =COUNTIF('Судовые документы'!H6:H12,"Н/Д")+COUNTIF('Таможенные документы'!H6:H10,"Н/Д")+COUNTIF('Экспортные грузы'!H6:H10,"Н/Д")+COUNTIF(Терминал!H6:H21,"Н/Д")+COUNTIF('ЖД грузы'!H6:H15,"Н/Д") -> 3 | C27: =IF(('Судовые документы'!A4+'Таможенные документы'!A4+'Экспортные грузы'!A4+Терминал!A4+'ЖД грузы'!A4)=0,0,B27/('Судовые документы'!A4+'Таможенные документы'!A4+'Экспортные грузы'!A4+Терминал!A4+'ЖД грузы'!A4)) -> 0.069767442 | E27: Итого | F27: =IFERROR(SUM(F17:F26),"0") -> 43 | G27: =IFERROR(SUM(G17:G25),"0") -> 3231
A28: Итого | B28: =IFERROR(SUM(B16:B27),"0") -> 44 | C28: =SUM(C16:C27) -> 1.0232558
A29: 💡 Вноси данные на листах разделов → Реестр и Дашборд обновляются автоматически

Sheet 📋 Реестр
A1: РЕЕСТР ЗАДАЧ АВТОМАТИЗАЦИИ СЦ СОЛВО 2026
A2: Сводный реестр — данные подтягиваются автоматически из листов по разделам. Правки вноси на листах разделов.
A3: № | B3: Номер заявки | C3: Наименование | D3: Описание задачи | E3: Срок | F3: Статус СЦ | G3: Статус СОЛВО | H3: Релиз | I3: Ч/часов | J3: Оценена | K3: Категория | L3: Приоритет | M3: Примечания
A4: ▸ Обработка судовых документов
A5: ='Судовые документы'!A6 -> 1 | B5: ='Судовые документы'!B6 -> 4SC-1-RQ-CR-789 #3297986 | C5: ='Судовые документы'!C6 -> Автоматизация ДО 1 | D5: =IFERROR(IF(K5="Обработка судовых документов",INDEX('Судовые документы'!D:D,MATCH(A5,'Судовые документы'!A:A,0)),IF(K5="Оформление таможенных документов",INDEX('Таможенные документы'!D:D,MATCH(A5,'Таможенные документы'!A:A,0)),IF(K5="Оформление экспортных грузов",INDEX('Экспортные грузы'!D:D,MATCH(A5,'Экспортные грузы'!A:A,0)),IF(K5="Терминальные операции",INDEX(Терминал!D:D,MATCH(A5,Терминал!A:A,0)),IF(K5="Документальное оформление ЖД грузов",INDEX('ЖД грузы'!D:D,MATCH(A5,'ЖД грузы'!A:A,0)),""))))),"") -> Корректное формирование ДО1 для контейнеров с признаком SOC | E5: =IFERROR(IF(K5="Обработка судовых документов",INDEX('Судовые документы'!E:E,MATCH(A5,'Судовые документы'!A:A,0)),IF(K5="Оформление таможенных документов",INDEX('Таможенные документы'!E:E,MATCH(A5,'Таможенные документы'!A:A,0)),IF(K5="Оформление экспортных грузов",INDEX('Экспортные грузы'!E:E,MATCH(A5,'Экспортные грузы'!A:A,0)),IF(K5="Терминальные операции",INDEX(Терминал!E:E,MATCH(A5,Терминал!A:A,0)),IF(K5="Документальное оформление ЖД грузов",INDEX('ЖД грузы'!E:E,MATCH(A5,'ЖД грузы'!A:A,0)),""))))),"") -> май 2026 | F5: =IFERROR(IF(K5="Обработка судовых документов",INDEX('Судовые документы'!F:F,MATCH(A5,'Судовые документы'!A:A,0)),IF(K5="Оформление таможенных документов",INDEX('Таможенные документы'!F:F,MATCH(A5,'Таможенные документы'!A:A,0)),IF(K5="Оформление экспортных грузов",INDEX('Экспортные грузы'!F:F,MATCH(A5,'Экспортные грузы'!A:A,0)),IF(K5="Терминальные операции",INDEX(Терминал!F:F,MATCH(A5,Терминал!A:A,0)),IF(K5="Документальное оформление ЖД грузов",INDEX('ЖД грузы'!F:F,MATCH(A5,'ЖД грузы'!A:A,0)),""))))),"") -> В работе | G5: =IFERROR(IF(K5="Обработка судовых документов",INDEX('Судовые документы'!G:G,MATCH(A5,'Судовые документы'!A:A,0)),IF(K5="Оформление таможенных документов",INDEX('Таможенные документы'!G:G,MATCH(A5,'Таможенные документы'!A:A,0)),IF(K5="Оформление экспортных грузов",INDEX('Экспортные грузы'!G:G,MATCH(A5,'Экспортные грузы'!A:A,0)),IF(K5="Терминальные операции",INDEX(Терминал!G:G,MATCH(A5,Терминал!A:A,0)),IF(K5="Документальное оформление ЖД грузов",INDEX('ЖД грузы'!G:G,MATCH(A5,'ЖД грузы'!A:A,0)),""))))),"") -> Тестирование | H5: =IFERROR(IF(K5="Обработка судовых документов",INDEX('Судовые документы'!H:H,MATCH(A5,'Судовые документы'!A:A,0)),IF(K5="Оформление таможенных документов",INDEX('Таможенные документы'!H:H,MATCH(A5,'Таможенные документы'!A:A,0)),IF(K5="Оформление экспортных грузов",INDEX('Экспортные грузы'!H:H,MATCH(A5,'Экспортные грузы'!A:A,0)),IF(K5="Терминальные операции",INDEX(Терминал!H:H,MATCH(A5,Терминал!A:A,0)),IF(K5="Документальное оформление ЖД грузов",INDEX('ЖД грузы'!H:H,MATCH(A5,'ЖД грузы'!A:A,0)),""))))),"") -> 7.4.10 | I5: =IFERROR(IF(K5="Обработка судовых документов",INDEX('Судовые документы'!I:I,MATCH(A5,'Судовые документы'!A:A,0)),IF(K5="Оформление таможенных документов",INDEX('Таможенные документы'!I:I,MATCH(A5,'Таможенные документы'!A:A,0)),IF(K5="Оформление экспортных грузов",INDEX('Экспортные грузы'!I:I,MATCH(A5,'Экспортные грузы'!A:A,0)),IF(K5="Терминальные операции",INDEX(Терминал!I:I,MATCH(A5,Терминал!A:A,0)),IF(K5="Документальное оформление ЖД грузов",INDEX('ЖД грузы'!I:I,MATCH(A5,'ЖД грузы'!A:A,0)),""))))),"") -> 235 | J5: =IFERROR(IF(K5="Обработка судовых документов",INDEX('Судовые документы'!J:J,MATCH(A5,'Судовые документы'!A:A,0)),IF(K5="Оформление таможенных документов",INDEX('Таможенные документы'!J:J,MATCH(A5,'Таможенные документы'!A:A,0)),IF(K5="Оформление экспортных грузов",INDEX('Экспортные грузы'!J:J,MATCH(A5,'Экспортные грузы'!A:A,0)),IF(K5="Терминальные операции",INDEX(Терминал!J:J,MATCH(A5,Терминал!A:A,0)),IF(K5="Документальное оформление ЖД грузов",INDEX('ЖД грузы'!J:J,MATCH(A5,'ЖД грузы'!A:A,0)),""))))),"") -> Да | K5: Обработка судовых документов | L5: =IFERROR(IF(K5="Обработка судовых документов",INDEX('Судовые документы'!L:L,MATCH(A5,'Судовые документы'!A:A,0)),IF(K5="Оформление таможенных документов",INDEX('Таможенные документы'!L:L,MATCH(A5,'Таможенные документы'!A:A,0)),IF(K5="Оформление экспортных грузов",INDEX('Экспортные грузы'!L:L,MATCH(A5,'Экспортные грузы'!A:A,0)),IF(K5="Терминальные операции",INDEX(Терминал!L:L,MATCH(A5,Терминал!A:A,0)),IF(K5="Документальное оформление ЖД грузов",INDEX('ЖД грузы'!L:L,MATCH(A5,'ЖД грузы'!A:A,0)),""))))),"") -> Средний | M5: =IFERROR(IF(K5="Обработка судовых документов",INDEX('Судовые документы'!K:K,MATCH(A5,'Судовые документы'!A:A,0)),IF(K5="Оформление таможенных документов",INDEX('Таможенные документы'!K:K,MATCH(A5,'Таможенные документы'!A:A,0)),IF(K5="Оформление экспортных грузов",INDEX('Экспортные грузы'!K:K,MATCH(A5,'Экспортные грузы'!A:A,0)),IF(K5="Терминальные операции",INDEX(Терминал!K:K,MATCH(A5,Терминал!A:A,0)),IF(K5="Документальное оформление ЖД грузов",INDEX('ЖД грузы'!K:K,MATCH(A5,'ЖД грузы'!A:A,0)),""))))),"") -> 0
A6: ='Судовые документы'!A7 -> 2 | B6: ='Судовые документы'!B7 -> 3323631 | C6: ='Судовые документы'!C7 -> Автоматизация ДО 1 | D6: =IFERROR(IF(K6="Обработка судовых документов",INDEX('Судовые документы'!D:D,MATCH(A6,'Судовые документы'!A:A,0)),IF(K6="Оформление таможенных документов",INDEX('Таможенные документы'!D:D,MATCH(A6,'Таможенные документы'!A:A,0)),IF(K6="Оформление экспортных грузов",INDEX('Экспортные грузы'!D:D,MATCH(A6,'Экспортные грузы'!A:A,0)),IF(K6="Терминальные операции",INDEX(Терминал!D:D,MATCH(A6,Терминал!A:A,0)),IF(K6="Документальное оформление ЖД грузов",INDEX('ЖД грузы'!D:D,MATCH(A6,'ЖД грузы'!A:A,0)),""))))),"") -> Некорректный вес в ген. Акте из-за дублирования веса тары | E6: =IFERROR(IF(K6="Обработка судовых документов",INDEX('Судовые документы'!E:E,MATCH(A6,'Судовые документы'!A:A,0)),IF(K6="Оформление таможенных документов",INDEX('Таможенные документы'!E:E,MATCH(A6,'Таможенные документы'!A:A,0)),IF(K6="Оформление экспортных грузов",INDEX('Экспортные грузы'!E:E,MATCH(A6,'Экспортные грузы'!A:A,0)),IF(K6="Терминальные операции",INDEX(Терминал!E:E,MATCH(A6,Терминал!A:A,0)),IF(K6="Документальное оформление ЖД грузов",INDEX('ЖД грузы'!E:E,MATCH(A6,'ЖД грузы'!A:A,0)),""))))),"") -> май 2026 | F6: =IFERROR(IF(K6="Обработка судовых документов",INDEX('Судовые документы'!F:F,MATCH(A6,'Судовые документы'!A:A,0)),IF(K6="Оформление таможенных документов",INDEX('Таможенные документы'!F:F,MATCH(A6,'Таможенные документы'!A:A,0)),IF(K6="Оформление экспортных грузов",INDEX('Экспортные грузы'!F:F,MATCH(A6,'Экспортные грузы'!A:A,0)),IF(K6="Терминальные операции",INDEX(Терминал!F:F,MATCH(A6,Терминал!A:A,0)),IF(K6="Документальное оформление ЖД грузов",INDEX('ЖД грузы'!F:F,MATCH(A6,'ЖД грузы'!A:A,0)),""))))),"") -> Приостановлена | G6: =IFERROR(IF(K6="Обработка судовых документов",INDEX('Судовые документы'!G:G,MATCH(A6,'Судовые документы'!A:A,0)),IF(K6="Оформление таможенных документов",INDEX('Таможенные документы'!G:G,MATCH(A6,'Таможенные документы'!A:A,0)),IF(K6="Оформление экспортных грузов",INDEX('Экспортные грузы'!G:G,MATCH(A6,'Экспортные грузы'!A:A,0)),IF(K6="Терминальные операции",INDEX(Терминал!G:G,MATCH(A6,Терминал!A:A,0)),IF(K6="Документальное оформление ЖД грузов",INDEX('ЖД грузы'!G:G,MATCH(A6,'ЖД грузы'!A:A,0)),""))))),"") -> Тестирование | H6: =IFERROR(IF(K6="Обработка судовых документов",INDEX('Судовые документы'!H:H,MATCH(A6,'Судовые документы'!A:A,0)),IF(K6="Оформление таможенных документов",INDEX('Таможенные документы'!H:H,MATCH(A6,'Таможенные документы'!A:A,0)),IF(K6="Оформление экспортных грузов",INDEX('Экспортные грузы'!H:H,MATCH(A6,'Экспортные грузы'!A:A,0)),IF(K6="Терминальные операции",INDEX(Терминал!H:H,MATCH(A6,Терминал!A:A,0)),IF(K6="Документальное оформление ЖД грузов",INDEX('ЖД грузы'!H:H,MATCH(A6,'ЖД грузы'!A:A,0)),""))))),"") -> 7.4.10 | I6: =IFERROR(IF(K6="Обработка судовых документов",INDEX('Судовые документы'!I:I,MATCH(A6,'Судовые документы'!A:A,0)),IF(K6="Оформление таможенных документов",INDEX('Таможенные документы'!I:I,MATCH(A6,'Таможенные документы'!A:A,0)),IF(K6="Оформление экспортных грузов",INDEX('Экспортные грузы'!I:I,MATCH(A6,'Экспортные грузы'!A:A,0)),IF(K6="Терминальные операции",INDEX(Терминал!I:I,MATCH(A6,Терминал!A:A,0)),IF(K6="Документальное оформление ЖД грузов",INDEX('ЖД грузы'!I:I,MATCH(A6,'ЖД грузы'!A:A,0)),""))))),"") -> 0 | J6: =IFERROR(IF(K6="Обработка судовых документов",INDEX('Судовые документы'!J:J,MATCH(A6,'Судовые документы'!A:A,0)),IF(K6="Оформление таможенных документов",INDEX('Таможенные документы'!J:J,MATCH(A6,'Таможенные документы'!A:A,0)),IF(K6="Оформление экспортных грузов",INDEX('Экспортные грузы'!J:J,MATCH(A6,'Экспортные грузы'!A:A,0)),IF(K6="Терминальные операции",INDEX(Терминал!J:J,MATCH(A6,Терминал!A:A,0)),IF(K6="Документальное оформление ЖД грузов",INDEX('ЖД грузы'!J:J,MATCH(A6,'ЖД грузы'!A:A,0)),""))))),"") -> Нет | K6: Обработка судовых документов | L6: =IFERROR(IF(K6="Обработка судовых документов",INDEX('Судовые документы'!L:L,MATCH(A6,'Судовые документы'!A:A,0)),IF(K6="Оформление таможенных документов",INDEX('Таможенные документы'!L:L,MATCH(A6,'Таможенные документы'!A:A,0)),IF(K6="Оформление экспортных грузов",INDEX('Экспортные грузы'!L:L,MATCH(A6,'Экспортные грузы'!A:A,0)),IF(K6="Терминальные операции",INDEX(Терминал!L:L,MATCH(A6,Терминал!A:A,0)),IF(K6="Документальное оформление ЖД грузов",INDEX('ЖД грузы'!L:L,MATCH(A6,'ЖД грузы'!A:A,0)),""))))),"") -> Средний | M6: =IFERROR(IF(K6="Обработка судовых документов",INDEX('Судовые документы'!K:K,MATCH(A6,'Судовые документы'!A:A,0)),IF(K6="Оформление таможенных документов",INDEX('Таможенные документы'!K:K,MATCH(A6,'Таможенные документы'!A:A,0)),IF(K6="Оформление экспортных грузов",INDEX('Экспортные грузы'!K:K,MATCH(A6,'Экспортные грузы'!A:A,0)),IF(K6="Терминальные операции",INDEX(Терминал!K:K,MATCH(A6,Терминал!A:A,0)),IF(K6="Документальное оформление ЖД грузов",INDEX('ЖД грузы'!K:K,MATCH(A6,'ЖД грузы'!A:A,0)),""))))),"") -> 0
A7: ='Судовые документы'!A8 -> 3 | B7: ='Судовые документы'!B8 -> 4SC-RQ-CR-876 #3628043 | C7: ='Судовые документы'!C8 -> Загрузка EDI cuscar | D7: =IFERROR(IF(K7="Обработка судовых документов",INDEX('Судовые документы'!D:D,MATCH(A7,'Судовые документы'!A:A,0)),IF(K7="Оформление таможенных документов",INDEX('Таможенные документы'!D:D,MATCH(A7,'Таможенные документы'!A:A,0)),IF(K7="Оформление экспортных грузов",INDEX('Экспортные грузы'!D:D,MATCH(A7,'Экспортные грузы'!A:A,0)),IF(K7="Терминальные операции",INDEX(Терминал!D:D,MATCH(A7,Терминал!A:A,0)),IF(K7="Документальное оформление ЖД грузов",INDEX('ЖД грузы'!D:D,MATCH(A7,'ЖД грузы'!A:A,0)),""))))),"") -> Проверка ключевых параметров коносамента | E7: =IFERROR(IF(K7="Обработка судовых документов",INDEX('Судовые документы'!E:E,MATCH(A7,'Судовые документы'!A:A,0)),IF(K7="Оформление таможенных документов",INDEX('Таможенные документы'!E:E,MATCH(A7,'Таможенные документы'!A:A,0)),IF(K7="Оформление экспортных грузов",INDEX('Экспортные грузы'!E:E,MATCH(A7,'Экспортные грузы'!A:A,0)),IF(K7="Терминальные операции",INDEX(Терминал!E:E,MATCH(A7,Терминал!A:A,0)),IF(K7="Документальное оформление ЖД грузов",INDEX('ЖД грузы'!E:E,MATCH(A7,'ЖД грузы'!A:A,0)),""))))),"") -> ОПЭ | F7: =IFERROR(IF(K7="Обработка судовых документов",INDEX('Судовые документы'!F:F,MATCH(A7,'Судовые документы'!A:A,0)),IF(K7="Оформление таможенных документов",INDEX('Таможенные документы'!F:F,MATCH(A7,'Таможенные документы'!A:A,0)),IF(K7="Оформление экспортных грузов",INDEX('Экспортные грузы'!F:F,MATCH(A7,'Экспортные грузы'!A:A,0)),IF(K7="Терминальные операции",INDEX(Терминал!F:F,MATCH(A7,Терминал!A:A,0)),IF(K7="Документальное оформление ЖД грузов",INDEX('ЖД грузы'!F:F,MATCH(A7,'ЖД грузы'!A:A,0)),""))))),"") -> ОПЭ | G7: =IFERROR(IF(K7="Обработка судовых документов",INDEX('Судовые документы'!G:G,MATCH(A7,'Судовые документы'!A:A,0)),IF(K7="Оформление таможенных документов",INDEX('Таможенные документы'!G:G,MATCH(A7,'Таможенные документы'!A:A,0)),IF(K7="Оформление экспортных грузов",INDEX('Экспортные грузы'!G:G,MATCH(A7,'Экспортные грузы'!A:A,0)),IF(K7="Терминальные операции",INDEX(Терминал!G:G,MATCH(A7,Терминал!A:A,0)),IF(K7="Документальное оформление ЖД грузов",INDEX('ЖД грузы'!G:G,MATCH(A7,'ЖД грузы'!A:A,0)),""))))),"") -> Установлено | H7: =IFERROR(IF(K7="Обработка судовых документов",INDEX('Судовые документы'!H:H,MATCH(A7,'Судовые документы'!A:A,0)),IF(K7="Оформление таможенных документов",INDEX('Таможенные документы'!H:H,MATCH(A7,'Таможенные документы'!A:A,0)),IF(K7="Оформление экспортных грузов",INDEX('Экспортные грузы'!H:H,MATCH(A7,'Экспортные грузы'!A:A,0)),IF(K7="Терминальные операции",INDEX(Терминал!H:H,MATCH(A7,Терминал!A:A,0)),IF(K7="Документальное оформление ЖД грузов",INDEX('ЖД грузы'!H:H,MATCH(A7,'ЖД грузы'!A:A,0)),""))))),"") -> 7.4.8 | I7: =IFERROR(IF(K7="Обработка судовых документов",INDEX('Судовые документы'!I:I,MATCH(A7,'Судовые документы'!A:A,0)),IF(K7="Оформление таможенных документов",INDEX('Таможенные документы'!I:I,MATCH(A7,'Таможенные документы'!A:A,0)),IF(K7="Оформление экспортных грузов",INDEX('Экспортные грузы'!I:I,MATCH(A7,'Экспортные грузы'!A:A,0)),IF(K7="Терминальные операции",INDEX(Терминал!I:I,MATCH(A7,Терминал!A:A,0)),IF(K7="Документальное оформление ЖД грузов",INDEX('ЖД грузы'!I:I,MATCH(A7,'ЖД грузы'!A:A,0)),""))))),"") -> 144 | J7: =IFERROR(IF(K7="Обработка судовых документов",INDEX('Судовые документы'!J:J,MATCH(A7,'Судовые документы'!A:A,0)),IF(K7="Оформление таможенных документов",INDEX('Таможенные документы'!J:J,MATCH(A7,'Таможенные документы'!A:A,0)),IF(K7="Оформление экспортных грузов",INDEX('Экспортные грузы'!J:J,MATCH(A7,'Экспортные грузы'!A:A,0)),IF(K7="Терминальные операции",INDEX(Терминал!J:J,MATCH(A7,Терминал!A:A,0)),IF(K7="Документальное оформление ЖД грузов",INDEX('ЖД грузы'!J:J,MATCH(A7,'ЖД грузы'!A:A,0)),""))))),"") -> Да | K7: Обработка судовых документов | L7: =IFERROR(IF(K7="Обработка судовых документов",INDEX('Судовые документы'!L:L,MATCH(A7,'Судовые документы'!A:A,0)),IF(K7="Оформление таможенных документов",INDEX('Таможенные документы'!L:L,MATCH(A7,'Таможенные документы'!A:A,0)),IF(K7="Оформление экспортных грузов",INDEX('Экспортные грузы'!L:L,MATCH(A7,'Экспортные грузы'!A:A,0)),IF(K7="Терминальные операции",INDEX(Терминал!L:L,MATCH(A7,Терминал!A:A,0)),IF(K7="Документальное оформление ЖД грузов",INDEX('ЖД грузы'!L:L,MATCH(A7,'ЖД грузы'!A:A,0)),""))))),"") -> Средний | M7: =IFERROR(IF(K7="Обработка судовых документов",INDEX('Судовые документы'!K:K,MATCH(A7,'Судовые документы'!A:A,0)),IF(K7="Оформление таможенных документов",INDEX('Таможенные документы'!K:K,MATCH(A7,'Таможенные документы'!A:A,0)),IF(K7="Оформление экспортных грузов",INDEX('Экспортные грузы'!K:K,MATCH(A7,'Экспортные грузы'!A:A,0)),IF(K7="Терминальные операции",INDEX(Терминал!K:K,MATCH(A7,Терминал!A:A,0)),IF(K7="Документальное оформление ЖД грузов",INDEX('ЖД грузы'!K:K,MATCH(A7,'ЖД грузы'!A:A,0)),""))))),"") -> 0
A8: ='Судовые документы'!A9 -> 4 | B8: ='Судовые документы'!B9 -> 4SC-1-RQ-CR-779 #3283630 | C8: ='Судовые документы'!C9 -> Ген акт, А/И, ведомость приема импорта | D8: =IFERROR(IF(K8="Обработка судовых документов",INDEX('Судовые документы'!D:D,MATCH(A8,'Судовые документы'!A:A,0)),IF(K8="Оформление таможенных документов",INDEX('Таможенные документы'!D:D,MATCH(A8,'Таможенные документы'!A:A,0)),IF(K8="Оформление экспортных грузов",INDEX('Экспортные грузы'!D:D,MATCH(A8,'Экспортные грузы'!A:A,0)),IF(K8="Терминальные операции",INDEX(Терминал!D:D,MATCH(A8,Терминал!A:A,0)),IF(K8="Документальное оформление ЖД грузов",INDEX('ЖД грузы'!D:D,MATCH(A8,'ЖД грузы'!A:A,0)),""))))),"") -> Подписание ген акта, А/И агентом. Ведомость направляется агенту автоматически | E8: =IFERROR(IF(K8="Обработка судовых документов",INDEX('Судовые документы'!E:E,MATCH(A8,'Судовые документы'!A:A,0)),IF(K8="Оформление таможенных документов",INDEX('Таможенные документы'!E:E,MATCH(A8,'Таможенные документы'!A:A,0)),IF(K8="Оформление экспортных грузов",INDEX('Экспортные грузы'!E:E,MATCH(A8,'Экспортные грузы'!A:A,0)),IF(K8="Терминальные операции",INDEX(Терминал!E:E,MATCH(A8,Терминал!A:A,0)),IF(K8="Документальное оформление ЖД грузов",INDEX('ЖД грузы'!E:E,MATCH(A8,'ЖД грузы'!A:A,0)),""))))),"") -> выполнено | F8: =IFERROR(IF(K8="Обработка судовых документов",INDEX('Судовые документы'!F:F,MATCH(A8,'Судовые документы'!A:A,0)),IF(K8="Оформление таможенных документов",INDEX('Таможенные документы'!F:F,MATCH(A8,'Таможенные документы'!A:A,0)),IF(K8="Оформление экспортных грузов",INDEX('Экспортные грузы'!F:F,MATCH(A8,'Экспортные грузы'!A:A,0)),IF(K8="Терминальные операции",INDEX(Терминал!F:F,MATCH(A8,Терминал!A:A,0)),IF(K8="Документальное оформление ЖД грузов",INDEX('ЖД грузы'!F:F,MATCH(A8,'ЖД грузы'!A:A,0)),""))))),"") -> Выполнено | G8: =IFERROR(IF(K8="Обработка судовых документов",INDEX('Судовые документы'!G:G,MATCH(A8,'Судовые документы'!A:A,0)),IF(K8="Оформление таможенных документов",INDEX('Таможенные документы'!G:G,MATCH(A8,'Таможенные документы'!A:A,0)),IF(K8="Оформление экспортных грузов",INDEX('Экспортные грузы'!G:G,MATCH(A8,'Экспортные грузы'!A:A,0)),IF(K8="Терминальные операции",INDEX(Терминал!G:G,MATCH(A8,Терминал!A:A,0)),IF(K8="Документальное оформление ЖД грузов",INDEX('ЖД грузы'!G:G,MATCH(A8,'ЖД грузы'!A:A,0)),""))))),"") -> Выставлено | H8: =IFERROR(IF(K8="Обработка судовых документов",INDEX('Судовые документы'!H:H,MATCH(A8,'Судовые документы'!A:A,0)),IF(K8="Оформление таможенных документов",INDEX('Таможенные документы'!H:H,MATCH(A8,'Таможенные документы'!A:A,0)),IF(K8="Оформление экспортных грузов",INDEX('Экспортные грузы'!H:H,MATCH(A8,'Экспортные грузы'!A:A,0)),IF(K8="Терминальные операции",INDEX(Терминал!H:H,MATCH(A8,Терминал!A:A,0)),IF(K8="Документальное оформление ЖД грузов",INDEX('ЖД грузы'!H:H,MATCH(A8,'ЖД грузы'!A:A,0)),""))))),"") -> 7.4.5 | I8: =IFERROR(IF(K8="Обработка судовых документов",INDEX('Судовые документы'!I:I,MATCH(A8,'Судовые документы'!A:A,0)),IF(K8="Оформление таможенных документов",INDEX('Таможенные документы'!I:I,MATCH(A8,'Таможенные документы'!A:A,0)),IF(K8="Оформление экспортных грузов",INDEX('Экспортные грузы'!I:I,MATCH(A8,'Экспортные грузы'!A:A,0)),IF(K8="Терминальные операции",INDEX(Терминал!I:I,MATCH(A8,Терминал!A:A,0)),IF(K8="Документальное оформление ЖД грузов",INDEX('ЖД грузы'!I:I,MATCH(A8,'ЖД грузы'!A:A,0)),""))))),"") -> 110 | J8: =IFERROR(IF(K8="Обработка судовых документов",INDEX('Судовые документы'!J:J,MATCH(A8,'Судовые документы'!A:A,0)),IF(K8="Оформление таможенных документов",INDEX('Таможенные документы'!J:J,MATCH(A8,'Таможенные документы'!A:A,0)),IF(K8="Оформление экспортных грузов",INDEX('Экспортные грузы'!J:J,MATCH(A8,'Экспортные грузы'!A:A,0)),IF(K8="Терминальные операции",INDEX(Терминал!J:J,MATCH(A8,Терминал!A:A,0)),IF(K8="Документальное оформление ЖД грузов",INDEX('ЖД грузы'!J:J,MATCH(A8,'ЖД грузы'!A:A,0)),""))))),"") -> Да | K8: Обработка судовых документов | L8: =IFERROR(IF(K8="Обработка судовых документов",INDEX('Судовые документы'!L:L,MATCH(A8,'Судовые документы'!A:A,0)),IF(K8="Оформление таможенных документов",INDEX('Таможенные документы'!L:L,MATCH(A8,'Таможенные документы'!A:A,0)),IF(K8="Оформление экспортных грузов",INDEX('Экспортные грузы'!L:L,MATCH(A8,'Экспортные грузы'!A:A,0)),IF(K8="Терминальные операции",INDEX(Терминал!L:L,MATCH(A8,Терминал!A:A,0)),IF(K8="Документальное оформление ЖД грузов",INDEX('ЖД грузы'!L:L,MATCH(A8,'ЖД грузы'!A:A,0)),""))))),"") -> Средний | M8: =IFERROR(IF(K8="Обработка судовых документов",INDEX('Судовые документы'!K:K,MATCH(A8,'Судовые документы'!A:A,0)),IF(K8="Оформление таможенных документов",INDEX('Таможенные документы'!K:K,MATCH(A8,'Таможенные документы'!A:A,0)),IF(K8="Оформление экспортных грузов",INDEX('Экспортные грузы'!K:K,MATCH(A8,'Экспортные грузы'!A:A,0)),IF(K8="Терминальные операции",INDEX(Терминал!K:K,MATCH(A8,Терминал!A:A,0)),IF(K8="Документальное оформление ЖД грузов",INDEX('ЖД грузы'!K:K,MATCH(A8,'ЖД грузы'!A:A,0)),""))))),"") -> 0
A9: ='Судовые документы'!A10 -> 5 | B9: ='Судовые документы'!B10 -> 0 | C9: ='Судовые документы'!C10 -> Ведомость погрузки контейнеров на судно | D9: =IFERROR(IF(K9="Обработка судовых документов",INDEX('Судовые документы'!D:D,MATCH(A9,'Судовые документы'!A:A,0)),IF(K9="Оформление таможенных документов",INDEX('Таможенные документы'!D:D,MATCH(A9,'Таможенные документы'!A:A,0)),IF(K9="Оформление экспортных грузов",INDEX('Экспортные грузы'!D:D,MATCH(A9,'Экспортные грузы'!A:A,0)),IF(K9="Терминальные операции",INDEX(Терминал!D:D,MATCH(A9,Терминал!A:A,0)),IF(K9="Документальное оформление ЖД грузов",INDEX('ЖД грузы'!D:D,MATCH(A9,'ЖД грузы'!A:A,0)),""))))),"") -> Реализация подписания Ведомости погрузки с использованием ЭП в ЛКК | E9: =IFERROR(IF(K9="Обработка судовых документов",INDEX('Судовые документы'!E:E,MATCH(A9,'Судовые документы'!A:A,0)),IF(K9="Оформление таможенных документов",INDEX('Таможенные документы'!E:E,MATCH(A9,'Таможенные документы'!A:A,0)),IF(K9="Оформление экспортных грузов",INDEX('Экспортные грузы'!E:E,MATCH(A9,'Экспортные грузы'!A:A,0)),IF(K9="Терминальные операции",INDEX(Терминал!E:E,MATCH(A9,Терминал!A:A,0)),IF(K9="Документальное оформление ЖД грузов",INDEX('ЖД грузы'!E:E,MATCH(A9,'ЖД грузы'!A:A,0)),""))))),"") -> выполнено | F9: =IFERROR(IF(K9="Обработка судовых документов",INDEX('Судовые документы'!F:F,MATCH(A9,'Судовые документы'!A:A,0)),IF(K9="Оформление таможенных документов",INDEX('Таможенные документы'!F:F,MATCH(A9,'Таможенные документы'!A:A,0)),IF(K9="Оформление экспортных грузов",INDEX('Экспортные грузы'!F:F,MATCH(A9,'Экспортные грузы'!A:A,0)),IF(K9="Терминальные операции",INDEX(Терминал!F:F,MATCH(A9,Терминал!A:A,0)),IF(K9="Документальное оформление ЖД грузов",INDEX('ЖД грузы'!F:F,MATCH(A9,'ЖД грузы'!A:A,0)),""))))),"") -> Выполнено | G9: =IFERROR(IF(K9="Обработка судовых документов",INDEX('Судовые документы'!G:G,MATCH(A9,'Судовые документы'!A:A,0)),IF(K9="Оформление таможенных документов",INDEX('Таможенные документы'!G:G,MATCH(A9,'Таможенные документы'!A:A,0)),IF(K9="Оформление экспортных грузов",INDEX('Экспортные грузы'!G:G,MATCH(A9,'Экспортные грузы'!A:A,0)),IF(K9="Терминальные операции",INDEX(Терминал!G:G,MATCH(A9,Терминал!A:A,0)),IF(K9="Документальное оформление ЖД грузов",INDEX('ЖД грузы'!G:G,MATCH(A9,'ЖД грузы'!A:A,0)),""))))),"") -> Не СОЛВО | H9: =IFERROR(IF(K9="Обработка судовых документов",INDEX('Судовые документы'!H:H,MATCH(A9,'Судовые документы'!A:A,0)),IF(K9="Оформление таможенных документов",INDEX('Таможенные документы'!H:H,MATCH(A9,'Таможенные документы'!A:A,0)),IF(K9="Оформление экспортных грузов",INDEX('Экспортные грузы'!H:H,MATCH(A9,'Экспортные грузы'!A:A,0)),IF(K9="Терминальные операции",INDEX(Терминал!H:H,MATCH(A9,Терминал!A:A,0)),IF(K9="Документальное оформление ЖД грузов",INDEX('ЖД грузы'!H:H,MATCH(A9,'ЖД грузы'!A:A,0)),""))))),"") -> Не СОЛВО | I9: =IFERROR(IF(K9="Обработка судовых документов",INDEX('Судовые документы'!I:I,MATCH(A9,'Судовые документы'!A:A,0)),IF(K9="Оформление таможенных документов",INDEX('Таможенные документы'!I:I,MATCH(A9,'Таможенные документы'!A:A,0)),IF(K9="Оформление экспортных грузов",INDEX('Экспортные грузы'!I:I,MATCH(A9,'Экспортные грузы'!A:A,0)),IF(K9="Терминальные операции",INDEX(Терминал!I:I,MATCH(A9,Терминал!A:A,0)),IF(K9="Документальное оформление ЖД грузов",INDEX('ЖД грузы'!I:I,MATCH(A9,'ЖД грузы'!A:A,0)),""))))),"") -> 0 | J9: =IFERROR(IF(K9="Обработка судовых документов",INDEX('Судовые документы'!J:J,MATCH(A9,'Судовые документы'!A:A,0)),IF(K9="Оформление таможенных документов",INDEX('Таможенные документы'!J:J,MATCH(A9,'Таможенные документы'!A:A,0)),IF(K9="Оформление экспортных грузов",INDEX('Экспортные грузы'!J:J,MATCH(A9,'Экспортные грузы'!A:A,0)),IF(K9="Терминальные операции",INDEX(Терминал!J:J,MATCH(A9,Терминал!A:A,0)),IF(K9="Документальное оформление ЖД грузов",INDEX('ЖД грузы'!J:J,MATCH(A9,'ЖД грузы'!A:A,0)),""))))),"") -> Да | K9: Обработка судовых документов | L9: =IFERROR(IF(K9="Обработка судовых документов",INDEX('Судовые документы'!L:L,MATCH(A9,'Судовые документы'!A:A,0)),IF(K9="Оформление таможенных документов",INDEX('Таможенные документы'!L:L,MATCH(A9,'Таможенные документы'!A:A,0)),IF(K9="Оформление экспортных грузов",INDEX('Экспортные грузы'!L:L,MATCH(A9,'Экспортные грузы'!A:A,0)),IF(K9="Терминальные операции",INDEX(Терминал!L:L,MATCH(A9,Терминал!A:A,0)),IF(K9="Документальное оформление ЖД грузов",INDEX('ЖД грузы'!L:L,MATCH(A9,'ЖД грузы'!A:A,0)),""))))),"") -> Средний | M9: =IFERROR(IF(K9="Обработка судовых документов",INDEX('Судовые документы'!K:K,MATCH(A9,'Судовые документы'!A:A,0)),IF(K9="Оформление таможенных документов",INDEX('Таможенные документы'!K:K,MATCH(A9,'Таможенные документы'!A:A,0)),IF(K9="Оформление экспортных грузов",INDEX('Экспортные грузы'!K:K,MATCH(A9,'Экспортные грузы'!A:A,0)),IF(K9="Терминальные операции",INDEX(Терминал!K:K,MATCH(A9,Терминал!A:A,0)),IF(K9="Документальное оформление ЖД грузов",INDEX('ЖД грузы'!K:K,MATCH(A9,'ЖД грузы'!A:A,0)),""))))),"") -> 0
A10: ='Судовые документы'!A11 -> 6 | B10: ='Судовые документы'!B11 -> 4SC-RQ-CR-984 #4012275 | C10: ='Судовые документы'!C11 -> Приемка трансшипмента, ПРР 2й категории | D10: =IFERROR(IF(K10="Обработка судовых документов",INDEX('Судовые документы'!D:D,MATCH(A10,'Судовые документы'!A:A,0)),IF(K10="Оформление таможенных документов",INDEX('Таможенные документы'!D:D,MATCH(A10,'Таможенные документы'!A:A,0)),IF(K10="Оформление экспортных грузов",INDEX('Экспортные грузы'!D:D,MATCH(A10,'Экспортные грузы'!A:A,0)),IF(K10="Терминальные операции",INDEX(Терминал!D:D,MATCH(A10,Терминал!A:A,0)),IF(K10="Документальное оформление ЖД грузов",INDEX('ЖД грузы'!D:D,MATCH(A10,'ЖД грузы'!A:A,0)),""))))),"") -> Обработка трансшипмента при загрузке коносамента | E10: =IFERROR(IF(K10="Обработка судовых документов",INDEX('Судовые документы'!E:E,MATCH(A10,'Судовые документы'!A:A,0)),IF(K10="Оформление таможенных документов",INDEX('Таможенные документы'!E:E,MATCH(A10,'Таможенные документы'!A:A,0)),IF(K10="Оформление экспортных грузов",INDEX('Экспортные грузы'!E:E,MATCH(A10,'Экспортные грузы'!A:A,0)),IF(K10="Терминальные операции",INDEX(Терминал!E:E,MATCH(A10,Терминал!A:A,0)),IF(K10="Документальное оформление ЖД грузов",INDEX('ЖД грузы'!E:E,MATCH(A10,'ЖД грузы'!A:A,0)),""))))),"") -> май 2026 | F10: =IFERROR(IF(K10="Обработка судовых документов",INDEX('Судовые документы'!F:F,MATCH(A10,'Судовые документы'!A:A,0)),IF(K10="Оформление таможенных документов",INDEX('Таможенные документы'!F:F,MATCH(A10,'Таможенные документы'!A:A,0)),IF(K10="Оформление экспортных грузов",INDEX('Экспортные грузы'!F:F,MATCH(A10,'Экспортные грузы'!A:A,0)),IF(K10="Терминальные операции",INDEX(Терминал!F:F,MATCH(A10,Терминал!A:A,0)),IF(K10="Документальное оформление ЖД грузов",INDEX('ЖД грузы'!F:F,MATCH(A10,'ЖД грузы'!A:A,0)),""))))),"") -> В работе | G10: =IFERROR(IF(K10="Обработка судовых документов",INDEX('Судовые документы'!G:G,MATCH(A10,'Судовые документы'!A:A,0)),IF(K10="Оформление таможенных документов",INDEX('Таможенные документы'!G:G,MATCH(A10,'Таможенные документы'!A:A,0)),IF(K10="Оформление экспортных грузов",INDEX('Экспортные грузы'!G:G,MATCH(A10,'Экспортные грузы'!A:A,0)),IF(K10="Терминальные операции",INDEX(Терминал!G:G,MATCH(A10,Терминал!A:A,0)),IF(K10="Документальное оформление ЖД грузов",INDEX('ЖД грузы'!G:G,MATCH(A10,'ЖД грузы'!A:A,0)),""))))),"") -> Разработка | H10: =IFERROR(IF(K10="Обработка судовых документов",INDEX('Судовые документы'!H:H,MATCH(A10,'Судовые документы'!A:A,0)),IF(K10="Оформление таможенных документов",INDEX('Таможенные документы'!H:H,MATCH(A10,'Таможенные документы'!A:A,0)),IF(K10="Оформление экспортных грузов",INDEX('Экспортные грузы'!H:H,MATCH(A10,'Экспортные грузы'!A:A,0)),IF(K10="Терминальные операции",INDEX(Терминал!H:H,MATCH(A10,Терминал!A:A,0)),IF(K10="Документальное оформление ЖД грузов",INDEX('ЖД грузы'!H:H,MATCH(A10,'ЖД грузы'!A:A,0)),""))))),"") -> 7.4.10 | I10: =IFERROR(IF(K10="Обработка судовых документов",INDEX('Судовые документы'!I:I,MATCH(A10,'Судовые документы'!A:A,0)),IF(K10="Оформление таможенных документов",INDEX('Таможенные документы'!I:I,MATCH(A10,'Таможенные документы'!A:A,0)),IF(K10="Оформление экспортных грузов",INDEX('Экспортные грузы'!I:I,MATCH(A10,'Экспортные грузы'!A:A,0)),IF(K10="Терминальные операции",INDEX(Терминал!I:I,MATCH(A10,Терминал!A:A,0)),IF(K10="Документальное оформление ЖД грузов",INDEX('ЖД грузы'!I:I,MATCH(A10,'ЖД грузы'!A:A,0)),""))))),"") -> 24 | J10: =IFERROR(IF(K10="Обработка судовых документов",INDEX('Судовые документы'!J:J,MATCH(A10,'Судовые документы'!A:A,0)),IF(K10="Оформление таможенных документов",INDEX('Таможенные документы'!J:J,MATCH(A10,'Таможенные документы'!A:A,0)),IF(K10="Оформление экспортных грузов",INDEX('Экспортные грузы'!J:J,MATCH(A10,'Экспортные грузы'!A:A,0)),IF(K10="Терминальные операции",INDEX(Терминал!J:J,MATCH(A10,Терминал!A:A,0)),IF(K10="Документальное оформление ЖД грузов",INDEX('ЖД грузы'!J:J,MATCH(A10,'ЖД грузы'!A:A,0)),""))))),"") -> Да | K10: Обработка судовых документов | L10: =IFERROR(IF(K10="Обработка судовых документов",INDEX('Судовые документы'!L:L,MATCH(A10,'Судовые документы'!A:A,0)),IF(K10="Оформление таможенных документов",INDEX('Таможенные документы'!L:L,MATCH(A10,'Таможенные документы'!A:A,0)),IF(K10="Оформление экспортных грузов",INDEX('Экспортные грузы'!L:L,MATCH(A10,'Экспортные грузы'!A:A,0)),IF(K10="Терминальные операции",INDEX(Терминал!L:L,MATCH(A10,Терминал!A:A,0)),IF(K10="Документальное оформление ЖД грузов",INDEX('ЖД грузы'!L:L,MATCH(A10,'ЖД грузы'!A:A,0)),""))))),"") -> Средний | M10: =IFERROR(IF(K10="Обработка судовых документов",INDEX('Судовые документы'!K:K,MATCH(A10,'Судовые документы'!A:A,0)),IF(K10="Оформление таможенных документов",INDEX('Таможенные документы'!K:K,MATCH(A10,'Таможенные документы'!A:A,0)),IF(K10="Оформление экспортных грузов",INDEX('Экспортные грузы'!K:K,MATCH(A10,'Экспортные грузы'!A:A,0)),IF(K10="Терминальные операции",INDEX(Терминал!K:K,MATCH(A10,Терминал!A:A,0)),IF(K10="Документальное оформление ЖД грузов",INDEX('ЖД грузы'!K:K,MATCH(A10,'ЖД грузы'!A:A,0)),""))))),"") -> 0
A11: ='Судовые документы'!A12 -> 7 | B11: ='Судовые документы'!B12 -> 4SC-RQ-CR-988 #4032163 | C11: ='Судовые документы'!C12 -> Обработка на т/х порожних контейнеров (каботаж) | D11: Добавить направление «Внутренний» и прием в квоту (депо) | E11: 2026 | F11: В работе | G11: Аналитика | H11: 7.4.11 | I11: 0 | J11: Нет | K11: Обработка судовых документов | L11: Средний | M11: =IFERROR(IF(K11="Обработка судовых документов",INDEX('Судовые документы'!K:K,MATCH(A11,'Судовые документы'!A:A,0)),IF(K11="Оформление таможенных документов",INDEX('Таможенные документы'!K:K,MATCH(A11,'Таможенные документы'!A:A,0)),IF(K11="Оформление экспортных грузов",INDEX('Экспортные грузы'!K:K,MATCH(A11,'Экспортные грузы'!A:A,0)),IF(K11="Терминальные операции",INDEX(Терминал!K:K,MATCH(A11,Терминал!A:A,0)),IF(K11="Документальное оформление ЖД грузов",INDEX('ЖД грузы'!K:K,MATCH(A11,'ЖД грузы'!A:A,0)),""))))),"") -> 0
A12: ▸ Оформление таможенных документов
A13: ='Таможенные документы'!A6 -> 8 | B13: ='Таможенные документы'!B6 -> 4SC-1-RQ-CR-342 #2361714 | C13: ='Таможенные документы'!C6 -> Контроль выпуска и автоматизация ДО 2 | D13: =IFERROR(IF(K13="Обработка судовых документов",INDEX('Судовые документы'!D:D,MATCH(A13,'Судовые документы'!A:A,0)),IF(K13="Оформление таможенных документов",INDEX('Таможенные документы'!D:D,MATCH(A13,'Таможенные документы'!A:A,0)),IF(K13="Оформление экспортных грузов",INDEX('Экспортные грузы'!D:D,MATCH(A13,'Экспортные грузы'!A:A,0)),IF(K13="Терминальные операции",INDEX(Терминал!D:D,MATCH(A13,Терминал!A:A,0)),IF(K13="Документальное оформление ЖД грузов",INDEX('ЖД грузы'!D:D,MATCH(A13,'ЖД грузы'!A:A,0)),""))))),"") -> Создание КА в СОЛВО, автоматическое формирование и отправка ДО2 | E13: =IFERROR(IF(K13="Обработка судовых документов",INDEX('Судовые документы'!E:E,MATCH(A13,'Судовые документы'!A:A,0)),IF(K13="Оформление таможенных документов",INDEX('Таможенные документы'!E:E,MATCH(A13,'Таможенные документы'!A:A,0)),IF(K13="Оформление экспортных грузов",INDEX('Экспортные грузы'!E:E,MATCH(A13,'Экспортные грузы'!A:A,0)),IF(K13="Терминальные операции",INDEX(Терминал!E:E,MATCH(A13,Терминал!A:A,0)),IF(K13="Документальное оформление ЖД грузов",INDEX('ЖД грузы'!E:E,MATCH(A13,'ЖД грузы'!A:A,0)),""))))),"") -> выполнено | F13: =IFERROR(IF(K13="Обработка судовых документов",INDEX('Судовые документы'!F:F,MATCH(A13,'Судовые документы'!A:A,0)),IF(K13="Оформление таможенных документов",INDEX('Таможенные документы'!F:F,MATCH(A13,'Таможенные документы'!A:A,0)),IF(K13="Оформление экспортных грузов",INDEX('Экспортные грузы'!F:F,MATCH(A13,'Экспортные грузы'!A:A,0)),IF(K13="Терминальные операции",INDEX(Терминал!F:F,MATCH(A13,Терминал!A:A,0)),IF(K13="Документальное оформление ЖД грузов",INDEX('ЖД грузы'!F:F,MATCH(A13,'ЖД грузы'!A:A,0)),""))))),"") -> В работе | G13: =IFERROR(IF(K13="Обработка судовых документов",INDEX('Судовые документы'!G:G,MATCH(A13,'Судовые документы'!A:A,0)),IF(K13="Оформление таможенных документов",INDEX('Таможенные документы'!G:G,MATCH(A13,'Таможенные документы'!A:A,0)),IF(K13="Оформление экспортных грузов",INDEX('Экспортные грузы'!G:G,MATCH(A13,'Экспортные грузы'!A:A,0)),IF(K13="Терминальные операции",INDEX(Терминал!G:G,MATCH(A13,Терминал!A:A,0)),IF(K13="Документальное оформление ЖД грузов",INDEX('ЖД грузы'!G:G,MATCH(A13,'ЖД грузы'!A:A,0)),""))))),"") -> Установлено | H13: =IFERROR(IF(K13="Обработка судовых документов",INDEX('Судовые документы'!H:H,MATCH(A13,'Судовые документы'!A:A,0)),IF(K13="Оформление таможенных документов",INDEX('Таможенные документы'!H:H,MATCH(A13,'Таможенные документы'!A:A,0)),IF(K13="Оформление экспортных грузов",INDEX('Экспортные грузы'!H:H,MATCH(A13,'Экспортные грузы'!A:A,0)),IF(K13="Терминальные операции",INDEX(Терминал!H:H,MATCH(A13,Терминал!A:A,0)),IF(K13="Документальное оформление ЖД грузов",INDEX('ЖД грузы'!H:H,MATCH(A13,'ЖД грузы'!A:A,0)),""))))),"") -> 7.4.4 | I13: =IFERROR(IF(K13="Обработка судовых документов",INDEX('Судовые документы'!I:I,MATCH(A13,'Судовые документы'!A:A,0)),IF(K13="Оформление таможенных документов",INDEX('Таможенные документы'!I:I,MATCH(A13,'Таможенные документы'!A:A,0)),IF(K13="Оформление экспортных грузов",INDEX('Экспортные грузы'!I:I,MATCH(A13,'Экспортные грузы'!A:A,0)),IF(K13="Терминальные операции",INDEX(Терминал!I:I,MATCH(A13,Терминал!A:A,0)),IF(K13="Документальное оформление ЖД грузов",INDEX('ЖД грузы'!I:I,MATCH(A13,'ЖД грузы'!A:A,0)),""))))),"") -> 780 | J13: =IFERROR(IF(K13="Обработка судовых документов",INDEX('Судовые документы'!J:J,MATCH(A13,'Судовые документы'!A:A,0)),IF(K13="Оформление таможенных документов",INDEX('Таможенные документы'!J:J,MATCH(A13,'Таможенные документы'!A:A,0)),IF(K13="Оформление экспортных грузов",INDEX('Экспортные грузы'!J:J,MATCH(A13,'Экспортные грузы'!A:A,0)),IF(K13="Терминальные операции",INDEX(Терминал!J:J,MATCH(A13,Терминал!A:A,0)),IF(K13="Документальное оформление ЖД грузов",INDEX('ЖД грузы'!J:J,MATCH(A13,'ЖД грузы'!A:A,0)),""))))),"") -> Да | K13: Оформление таможенных документов | L13: =IFERROR(IF(K13="Обработка судовых документов",INDEX('Судовые документы'!L:L,MATCH(A13,'Судовые документы'!A:A,0)),IF(K13="Оформление таможенных документов",INDEX('Таможенные документы'!L:L,MATCH(A13,'Таможенные документы'!A:A,0)),IF(K13="Оформление экспортных грузов",INDEX('Экспортные грузы'!L:L,MATCH(A13,'Экспортные грузы'!A:A,0)),IF(K13="Терминальные операции",INDEX(Терминал!L:L,MATCH(A13,Терминал!A:A,0)),IF(K13="Документальное оформление ЖД грузов",INDEX('ЖД грузы'!L:L,MATCH(A13,'ЖД грузы'!A:A,0)),""))))),"") -> Средний | M13: =IFERROR(IF(K13="Обработка судовых документов",INDEX('Судовые документы'!K:K,MATCH(A13,'Судовые документы'!A:A,0)),IF(K13="Оформление таможенных документов",INDEX('Таможенные документы'!K:K,MATCH(A13,'Таможенные документы'!A:A,0)),IF(K13="Оформление экспортных грузов",INDEX('Экспортные грузы'!K:K,MATCH(A13,'Экспортные грузы'!A:A,0)),IF(K13="Терминальные операции",INDEX(Терминал!K:K,MATCH(A13,Терминал!A:A,0)),IF(K13="Документальное оформление ЖД грузов",INDEX('ЖД грузы'!K:K,MATCH(A13,'ЖД грузы'!A:A,0)),""))))),"") -> 0
A14: ='Таможенные документы'!A7 -> 9 | B14: ='Таможенные документы'!B7 -> 4SC-RQ-CR-704 #3030536 | C14: ='Таможенные документы'!C7 -> ВТТ транзит для Бананов | D14: =IFERROR(IF(K14="Обработка судовых документов",INDEX('Судовые документы'!D:D,MATCH(A14,'Судовые документы'!A:A,0)),IF(K14="Оформление таможенных документов",INDEX('Таможенные документы'!D:D,MATCH(A14,'Таможенные документы'!A:A,0)),IF(K14="Оформление экспортных грузов",INDEX('Экспортные грузы'!D:D,MATCH(A14,'Экспортные грузы'!A:A,0)),IF(K14="Терминальные операции",INDEX(Терминал!D:D,MATCH(A14,Терминал!A:A,0)),IF(K14="Документальное оформление ЖД грузов",INDEX('ЖД грузы'!D:D,MATCH(A14,'ЖД грузы'!A:A,0)),""))))),"") -> Автоматическая прогрузка таможенного разрешения после получения уведомления | E14: =IFERROR(IF(K14="Обработка судовых документов",INDEX('Судовые документы'!E:E,MATCH(A14,'Судовые документы'!A:A,0)),IF(K14="Оформление таможенных документов",INDEX('Таможенные документы'!E:E,MATCH(A14,'Таможенные документы'!A:A,0)),IF(K14="Оформление экспортных грузов",INDEX('Экспортные грузы'!E:E,MATCH(A14,'Экспортные грузы'!A:A,0)),IF(K14="Терминальные операции",INDEX(Терминал!E:E,MATCH(A14,Терминал!A:A,0)),IF(K14="Документальное оформление ЖД грузов",INDEX('ЖД грузы'!E:E,MATCH(A14,'ЖД грузы'!A:A,0)),""))))),"") -> 2026 | F14: =IFERROR(IF(K14="Обработка судовых документов",INDEX('Судовые документы'!F:F,MATCH(A14,'Судовые документы'!A:A,0)),IF(K14="Оформление таможенных документов",INDEX('Таможенные документы'!F:F,MATCH(A14,'Таможенные документы'!A:A,0)),IF(K14="Оформление экспортных грузов",INDEX('Экспортные грузы'!F:F,MATCH(A14,'Экспортные грузы'!A:A,0)),IF(K14="Терминальные операции",INDEX(Терминал!F:F,MATCH(A14,Терминал!A:A,0)),IF(K14="Документальное оформление ЖД грузов",INDEX('ЖД грузы'!F:F,MATCH(A14,'ЖД грузы'!A:A,0)),""))))),"") -> В работе | G14: =IFERROR(IF(K14="Обработка судовых документов",INDEX('Судовые документы'!G:G,MATCH(A14,'Судовые документы'!A:A,0)),IF(K14="Оформление таможенных документов",INDEX('Таможенные документы'!G:G,MATCH(A14,'Таможенные документы'!A:A,0)),IF(K14="Оформление экспортных грузов",INDEX('Экспортные грузы'!G:G,MATCH(A14,'Экспортные грузы'!A:A,0)),IF(K14="Терминальные операции",INDEX(Терминал!G:G,MATCH(A14,Терминал!A:A,0)),IF(K14="Документальное оформление ЖД грузов",INDEX('ЖД грузы'!G:G,MATCH(A14,'ЖД грузы'!A:A,0)),""))))),"") -> Аналитика | H14: =IFERROR(IF(K14="Обработка судовых документов",INDEX('Судовые документы'!H:H,MATCH(A14,'Судовые документы'!A:A,0)),IF(K14="Оформление таможенных документов",INDEX('Таможенные документы'!H:H,MATCH(A14,'Таможенные документы'!A:A,0)),IF(K14="Оформление экспортных грузов",INDEX('Экспортные грузы'!H:H,MATCH(A14,'Экспортные грузы'!A:A,0)),IF(K14="Терминальные операции",INDEX(Терминал!H:H,MATCH(A14,Терминал!A:A,0)),IF(K14="Документальное оформление ЖД грузов",INDEX('ЖД грузы'!H:H,MATCH(A14,'ЖД грузы'!A:A,0)),""))))),"") -> 7.4.11 | I14: =IFERROR(IF(K14="Обработка судовых документов",INDEX('Судовые документы'!I:I,MATCH(A14,'Судовые документы'!A:A,0)),IF(K14="Оформление таможенных документов",INDEX('Таможенные документы'!I:I,MATCH(A14,'Таможенные документы'!A:A,0)),IF(K14="Оформление экспортных грузов",INDEX('Экспортные грузы'!I:I,MATCH(A14,'Экспортные грузы'!A:A,0)),IF(K14="Терминальные операции",INDEX(Терминал!I:I,MATCH(A14,Терминал!A:A,0)),IF(K14="Документальное оформление ЖД грузов",INDEX('ЖД грузы'!I:I,MATCH(A14,'ЖД грузы'!A:A,0)),""))))),"") -> 0 | J14: =IFERROR(IF(K14="Обработка судовых документов",INDEX('Судовые документы'!J:J,MATCH(A14,'Судовые документы'!A:A,0)),IF(K14="Оформление таможенных документов",INDEX('Таможенные документы'!J:J,MATCH(A14,'Таможенные документы'!A:A,0)),IF(K14="Оформление экспортных грузов",INDEX('Экспортные грузы'!J:J,MATCH(A14,'Экспортные грузы'!A:A,0)),IF(K14="Терминальные операции",INDEX(Терминал!J:J,MATCH(A14,Терминал!A:A,0)),IF(K14="Документальное оформление ЖД грузов",INDEX('ЖД грузы'!J:J,MATCH(A14,'ЖД грузы'!A:A,0)),""))))),"") -> Нет | K14: Оформление таможенных документов | L14: =IFERROR(IF(K14="Обработка судовых документов",INDEX('Судовые документы'!L:L,MATCH(A14,'Судовые документы'!A:A,0)),IF(K14="Оформление таможенных документов",INDEX('Таможенные документы'!L:L,MATCH(A14,'Таможенные документы'!A:A,0)),IF(K14="Оформление экспортных грузов",INDEX('Экспортные грузы'!L:L,MATCH(A14,'Экспортные грузы'!A:A,0)),IF(K14="Терминальные операции",INDEX(Терминал!L:L,MATCH(A14,Терминал!A:A,0)),IF(K14="Документальное оформление ЖД грузов",INDEX('ЖД грузы'!L:L,MATCH(A14,'ЖД грузы'!A:A,0)),""))))),"") -> Средний | M14: =IFERROR(IF(K14="Обработка судовых документов",INDEX('Судовые документы'!K:K,MATCH(A14,'Судовые документы'!A:A,0)),IF(K14="Оформление таможенных документов",INDEX('Таможенные документы'!K:K,MATCH(A14,'Таможенные документы'!A:A,0)),IF(K14="Оформление экспортных грузов",INDEX('Экспортные грузы'!K:K,MATCH(A14,'Экспортные грузы'!A:A,0)),IF(K14="Терминальные операции",INDEX(Терминал!K:K,MATCH(A14,Терминал!A:A,0)),IF(K14="Документальное оформление ЖД грузов",INDEX('ЖД грузы'!K:K,MATCH(A14,'ЖД грузы'!A:A,0)),""))))),"") -> 0
